<?xml version="1.0" ?>
<robot xmlns:xacro="http://www.ros.org/wiki/xacro" name="ernest">
<xacro:include filename="$(find description)/urdf/materials.xacro"/>
<xacro:macro name="ernest" params="prefix"> 
  <link name="base_link">
  </link>

  <joint name="frame_joint" type="fixed">
    <origin rpy="0 0 ${- pi/2}" xyz="-0.4 0 0.4"/>
    <parent link="base_link"/>
    <child link="chassis"/>
  </joint> 

  <link name="chassis">
    <inertial>
      <origin rpy="0 0 0" xyz="-1.0298688833211E-06 0.0295380349610433 0"/>
      <mass value="68.3444673293532"/>
      <inertia ixx="2.38407014740501" ixy="1.00458083063188E-05" ixz="-9.36310845540363E-07" iyy="2.67178308348484" iyz="0.00251180651218514" izz="4.62433309772227"/>
    </inertial>
    <visual>
      <origin rpy="0 0 0" xyz="0 0 0"/>
      <geometry>
        <mesh filename="package://description/meshes/chassis.STL"/>
      </geometry>
      <material name="white"/>
    </visual>
    <collision>
      <origin rpy="0 0 0" xyz="0 0 0"/>
      <geometry>
        <mesh filename="package://description/meshes/chassis.STL"/>
      </geometry>
    </collision> 
  </link>

  <link name="pivot">
    <inertial>
      <origin rpy="0 0 0" xyz="-5.83048022436035E-08 -0.0363481578557913 -0.0534922287892846"/>
      <mass value="1.21599360090943"/>
      <inertia ixx="0.00252807022514203" ixy="-4.02004758012849E-10" ixz="-8.09265660814765E-10" iyy="0.0022400253412425" iyz="-0.000203652777557111" izz="0.00252590889130123"/>
    </inertial>
    <visual>
      <origin rpy="0 0 0" xyz="0 0 0"/>
      <geometry>
        <mesh filename="package://description/meshes/pivot.STL"/>
      </geometry>
      <material name="black"/>
    </visual>
    <collision>
      <origin rpy="0 0 0" xyz="0 0 0"/>
      <geometry>
        <mesh filename="package://description/meshes/pivot.STL"/>
      </geometry>
    </collision>
  </link>

  <joint name="pivot_joint" type="revolute">
    <limit effort="0.001" lower="-0.8" upper="0.8" velocity="30"/>
    <origin rpy="0 0 3.13911747329568" xyz="0 0.4015 -0.00700000000000001"/>
    <parent link="chassis"/>
    <child link="pivot"/>
    <axis xyz="0 0 -1"/>
  </joint>


  <link name="bogie">
    <inertial>
      <origin rpy="0 0 0" xyz="1.79530299480868E-10 0.107565838050474 0.0507988190707989"/>
      <mass value="4.63613500742378"/>
      <inertia ixx="0.0176539151712099" ixy="1.33179894816995E-11" ixz="-1.80130416487432E-08" iyy="0.492085815595167" iyz="-2.75247894551671E-07" izz="0.50573206082967"/>
    </inertial>
    <visual>
      <origin rpy="0 0 0" xyz="0 0 0"/>
      <geometry>
        <mesh filename="package://description/meshes/bogie.STL"/>
      </geometry>
      <material name="white"/>
    </visual>
    <collision>
      <origin rpy="0 0 0" xyz="0 0 0"/>
      <geometry>
        <mesh filename="package://description/meshes/bogie.STL"/>
      </geometry>
    </collision>
  </link>

  <joint name="bogie_joint" type="continuous">
    <origin rpy="1.5707963267949 0.000529942236827729 0" xyz="0 -0.101800622452903 -0.0640000000000083"/>
    <parent link="pivot"/>
    <child link="bogie"/>
    <axis xyz="0 0 1"/>
  </joint>

  <link name="front_left_steer">
    <inertial>
      <origin rpy="0 0 0" xyz="-0.0214602071785041 -1.63416418175188E-08 -0.170809822421106"/>
      <mass value="3.15693347082843"/>
      <inertia ixx="0.00959564325201883" ixy="-6.90245158474706E-10" ixz="0.0016350665333109" iyy="0.0124240240946827" iyz="-1.50731012690546E-09" izz="0.0107772256212113"/>
    </inertial>
    <visual>
      <origin rpy="0 0 0" xyz="0 0 0"/>
      <geometry>
        <mesh filename="package://description/meshes/front_left_steer.STL"/>
      </geometry>
      <material name="black"/>
    </visual>
    <collision>
      <origin rpy="0 0 0" xyz="0 0 0"/>
      <geometry>
        <mesh filename="package://description/meshes/front_left_steer.STL"/>
      </geometry>
    </collision>
  </link>
  <joint name="front_left_steer_joint" type="revolute">
    <limit effort="50" lower="-0.8" upper="0.8" velocity="30"/>
    <origin rpy="-1.5707963267949 0.0208107531087718 0" xyz="0.399593578400315 0.05 0.0507993775470971"/>
    <parent link="bogie"/>
    <child link="front_left_steer"/>
    <axis xyz="0 0 -1"/>
  </joint>
  <link name="front_left_wheel">
    <inertial>
      <origin rpy="0 0 0" xyz="-3.33066907387547E-16 4.05231403988182E-15 -0.0103428040717592"/>
      <mass value="7.89516360300985"/>
      <inertia ixx="0.0721255226619386" ixy="5.85469173142172E-18" ixz="-4.01154803819637E-18" iyy="0.0721255226619386" iyz="-7.99937915386961E-18" izz="0.124903964328039"/>
    </inertial>
    <visual>
      <origin rpy="0 0 0" xyz="0 0 0"/>
      <geometry>
        <mesh filename="package://description/meshes/front_left_wheel.STL"/>
      </geometry>
      <material name="grey"/>
    </visual>
    <collision>
      <origin rpy="0 0 0" xyz="0 0 0"/>
      <geometry>
        <mesh filename="package://description/meshes/front_left_wheel.STL"/>
      </geometry>
      <friction>
        <ode>
          <mu>100000.0</mu>
          <mu2>100000.0</mu2>
        </ode>
        </friction>
        <contact>
          <ode>
            <min_depth>0.003</min_depth>
          </ode>
        </contact>
    </collision>
  </link>
  <joint name="front_left_wheel_joint" type="continuous">
    <origin rpy="1.57079632679491 0.0288958987838113 1.5707963267949" xyz="0 0 -0.214560184613926"/>
    <parent link="front_left_steer"/>
    <child link="front_left_wheel"/>
    <axis xyz="0 0 1"/>
  </joint>
  <link name="front_right_steer">
    <inertial>
      <origin rpy="0 0 0" xyz="-1.52169934430901E-08 0.0214602071253955 -0.170809822376615"/>
      <mass value="3.15693347612183"/>
      <inertia ixx="0.0124240240575744" ixy="6.60872662000606E-10" ixz="-1.54947980758551E-09" iyy="0.00959564336065084" iyz="-0.00163506652840397" izz="0.0107772257857585"/>
    </inertial>
    <visual>
      <origin rpy="0 0 0" xyz="0 0 0"/>
      <geometry>
        <mesh filename="package://description/meshes/front_right_steer.STL"/>
      </geometry>
      <material name="black"/>
    </visual>
    <collision>
      <origin rpy="0 0 0" xyz="0 0 0"/>
      <geometry>
        <mesh filename="package://description/meshes/front_right_steer.STL"/>
      </geometry>
    </collision>
  </link>
  <joint name="front_right_steer_joint" type="revolute">
    <limit effort="50" lower="-0.8" upper="0.8" velocity="30"/>
    <origin rpy="-1.57079632679545 -1.56850410535828 0" xyz="-0.399593578400314 0.05 0.0507993775470972"/>
    <parent link="bogie"/>
    <child link="front_right_steer"/>
    <axis xyz="0 0 -1"/>
  </joint>
  <link name="front_right_wheel">
    <inertial>
      <origin rpy="0 0 0" xyz="3.33066907387547E-16 2.77555756156289E-16 -0.0103428040717612"/>
      <mass value="7.89516360300985"/>
      <inertia ixx="0.0721255226619385" ixy="-3.46944695195361E-18" ixz="1.11723645742842E-18" iyy="0.0721255226619386" iyz="-2.28698895758661E-20" izz="0.124903964328039"/>
    </inertial>
    <visual>
      <origin rpy="0 0 0" xyz="0 0 0"/>
      <geometry>
        <mesh filename="package://description/meshes/front_right_wheel.STL"/>
      </geometry>
      <friction>
        <ode>
          <mu>100000.0</mu>
          <mu2>100000.0</mu2>
        </ode>
        </friction>
        <contact>
          <ode>
            <min_depth>0.003</min_depth>
          </ode>
        </contact>
      <material name="grey"/>
    </visual>
    <collision>
      <origin rpy="0 0 0" xyz="0 0 0"/>
      <geometry>
        <mesh filename="package://description/meshes/front_right_wheel.STL"/>
      </geometry>
    </collision>
  </link>
  <joint name="front_right_wheel_joint" type="continuous">
    <origin rpy="1.5707963267949 1.23836412201798 0" xyz="0 0 -0.214560184613926"/>
    <parent link="front_right_steer"/>
    <child link="front_right_wheel"/>
    <axis xyz="0 0 -1"/>
  </joint>
  <link name="rear_right_steer">
    <inertial>
      <origin rpy="0 0 0" xyz="-0.0214599012801062 -0.00011457141843102 -0.175249637742071"/>
      <mass value="3.15693347239416"/>
      <inertia ixx="0.00959572392851739" ixy="-1.50985192125477E-05" ixz="0.00163504324230246" iyy="0.0124239434676959" iyz="8.72654557966917E-06" izz="0.0107772257336762"/>
    </inertial>
    <visual>
      <origin rpy="0 0 0" xyz="0 0 0"/>
      <geometry>
        <mesh filename="package://description/meshes/rear_right_steer.STL"/>
      </geometry>
      <material name="black"/>
    </visual>
    <collision>
      <origin rpy="0 0 0" xyz="0 0 0"/>
      <geometry>
        <mesh filename="package://description/meshes/rear_right_steer.STL"/>
      </geometry>
    </collision>
  </link>
  <joint name="rear_right_steer_joint" type="revolute">
    <limit effort="50" lower="-0.8" upper="0.8" velocity="30"/>
    <origin rpy="0 0 0" xyz="0.4038086578651 -0.313808657865102 -0.01666"/>
    <parent link="chassis"/>
    <child link="rear_right_steer"/>
    <axis xyz="0 0 -1"/>
  </joint>
  <link name="rear_right_wheel">
    <inertial>
      <origin rpy="0 0 0" xyz="2.77555756156289E-17 2.22044604925031E-16 -0.0103428040717601"/>
      <mass value="7.89516360300985"/>
      <inertia ixx="0.0721255226619386" ixy="-2.88671200177212E-35" ixz="-5.84667280332668E-51" iyy="0.0721255226619387" iyz="-1.12757025938492E-17" izz="0.124903964328039"/>
    </inertial>
    <visual>
      <origin rpy="0 0 0" xyz="0 0 0"/>
      <geometry>
        <mesh filename="package://description/meshes/rear_right_wheel.STL"/>
      </geometry>
      <friction>
        <ode>
          <mu>100000.0</mu>
          <mu2>100000.0</mu2>
        </ode>
        </friction>
        <contact>
          <ode>
            <min_depth>0.003</min_depth>
          </ode>
        </contact>
      <material name="grey"/>
    </visual>
    <collision>
      <origin rpy="0 0 0" xyz="0 0 0"/>
      <geometry>
        <mesh filename="package://description/meshes/rear_right_wheel.STL"/>
      </geometry>
    </collision>
  </link>
  <joint name="rear_right_wheel_joint" type="continuous">
    <origin rpy="0.0053380848461707 1.5707963267949 0" xyz="0 0 -0.219"/>
    <parent link="rear_right_steer"/>
    <child link="rear_right_wheel"/>
    <axis xyz="0 0 -1"/>
  </joint>
  <link name="rear_left_steer">
    <inertial>
      <origin rpy="0 0 0" xyz="-1.54421406217686E-08 0.0214602071095881 -0.175249637732323"/>
      <mass value="3.15693347259842"/>
      <inertia ixx="0.0124240240655924" ixy="6.66699103828725E-10" ixz="-1.54116152780023E-09" iyy="0.00959564333765986" iyz="-0.00163506652927261" izz="0.0107772257496637"/>
    </inertial>
    <visual>
      <origin rpy="0 0 0" xyz="0 0 0"/>
      <geometry>
        <mesh filename="package://description/meshes/rear_left_steer.STL"/>
      </geometry>
      <material name="black"/>
    </visual>
    <collision>
      <origin rpy="0 0 0" xyz="0 0 0"/>
      <geometry>
        <mesh filename="package://description/meshes/rear_left_steer.STL"/>
      </geometry>
    </collision>
  </link>
  <joint name="rear_left_steer_joint" type="revolute">
    <limit effort="50" lower="-0.8" upper="0.8" velocity="30"/>
    <origin rpy="0 0 -1.56733797587802" xyz="-0.403808657865099 -0.313808657865101 -0.01666"/>
    <parent link="chassis"/>
    <child link="rear_left_steer"/>
    <axis xyz="0 0 -1"/>
  </joint>
  <link name="rear_left_wheel">
    <inertial>
      <origin rpy="0 0 0" xyz="1.66533453693773E-16 -2.77555756156289E-16 -0.0103428040717607"/>
      <mass value="7.89516360300985"/>
      <inertia ixx="0.0721255226619386" ixy="5.20417042793042E-18" ixz="-9.45288769135799E-19" iyy="0.0721255226619386" iyz="-7.73849300611529E-18" izz="0.124903964328039"/>
    </inertial>
    <visual>
      <origin rpy="0 0 0" xyz="0 0 0"/>
      <geometry>
        <mesh filename="package://description/meshes/rear_left_wheel.STL"/>
      </geometry>
      <friction>
        <ode>
          <mu>100000.0</mu>
          <mu2>100000.0</mu2>
        </ode>
        </friction>
        <contact>
          <ode>
            <min_depth>0.003</min_depth>
          </ode>
        </contact>
      <material name="grey"/>
    </visual>
    <collision>
      <origin rpy="0 0 0" xyz="0 0 0"/>
      <geometry>
        <mesh filename="package://description/meshes/rear_left_wheel.STL"/>
      </geometry>
    </collision>
  </link>
  <joint name="rear_left_wheel_joint" type="continuous">
    <origin rpy="-1.5707963267949 1.3424366648975 -3.14159265358979" xyz="0 0 -0.219"/>
    <parent link="rear_left_steer"/>
    <child link="rear_left_wheel"/>
    <axis xyz="0 0 1"/>
  </joint>
  


</xacro:macro>
</robot>
